[ERROR]2023.12.07 18:47:04 : 蠢问题拉
[ERROR]2023.12.07 19:20:32 : python执行的错误信息HTTPConnectionPool(host='192.168.3.22', port=9004): Max retries exceeded with url: /api/eod/all-business-date (Caused by ConnectTimeoutError(<urllib3.connection.HTTPConnection object at 0x10426c610>, 'Connection to 192.168.3.22 timed out. (connect timeout=None)'))
[ERROR]2023.12.07 19:20:32 : python执行时的错误：'ConnectTimeout' object has no attribute 'status_code'
